{
 "cells": [
  {
   "cell_type": "code",
   "execution_count": 17,
   "metadata": {},
   "outputs": [
    {
     "ename": "OSError",
     "evalue": "meta-llama/Llama-2-7b-chat-hf is not a local folder and is not a valid model identifier listed on 'https://huggingface.co/models'\nIf this is a private repository, make sure to pass a token having permission to this repo with `use_auth_token` or log in with `huggingface-cli login` and pass `use_auth_token=True`.",
     "output_type": "error",
     "traceback": [
      "\u001b[0;31m---------------------------------------------------------------------------\u001b[0m",
      "\u001b[0;31mHTTPError\u001b[0m                                 Traceback (most recent call last)",
      "File \u001b[0;32m~/ttmp/anaconda3/envs/baselines/lib/python3.11/site-packages/huggingface_hub/utils/_errors.py:269\u001b[0m, in \u001b[0;36mhf_raise_for_status\u001b[0;34m(response, endpoint_name)\u001b[0m\n\u001b[1;32m    268\u001b[0m \u001b[38;5;28;01mtry\u001b[39;00m:\n\u001b[0;32m--> 269\u001b[0m     response\u001b[38;5;241m.\u001b[39mraise_for_status()\n\u001b[1;32m    270\u001b[0m \u001b[38;5;28;01mexcept\u001b[39;00m HTTPError \u001b[38;5;28;01mas\u001b[39;00m e:\n",
      "File \u001b[0;32m~/ttmp/anaconda3/envs/baselines/lib/python3.11/site-packages/requests/models.py:1021\u001b[0m, in \u001b[0;36mResponse.raise_for_status\u001b[0;34m(self)\u001b[0m\n\u001b[1;32m   1020\u001b[0m \u001b[38;5;28;01mif\u001b[39;00m http_error_msg:\n\u001b[0;32m-> 1021\u001b[0m     \u001b[38;5;28;01mraise\u001b[39;00m HTTPError(http_error_msg, response\u001b[38;5;241m=\u001b[39m\u001b[38;5;28mself\u001b[39m)\n",
      "\u001b[0;31mHTTPError\u001b[0m: 401 Client Error: Unauthorized for url: https://huggingface.co/meta-llama/Llama-2-7b-chat-hf/resolve/main/tokenizer_config.json",
      "\nThe above exception was the direct cause of the following exception:\n",
      "\u001b[0;31mGatedRepoError\u001b[0m                            Traceback (most recent call last)",
      "File \u001b[0;32m~/ttmp/anaconda3/envs/baselines/lib/python3.11/site-packages/transformers/utils/hub.py:417\u001b[0m, in \u001b[0;36mcached_file\u001b[0;34m(path_or_repo_id, filename, cache_dir, force_download, resume_download, proxies, use_auth_token, revision, local_files_only, subfolder, repo_type, user_agent, _raise_exceptions_for_missing_entries, _raise_exceptions_for_connection_errors, _commit_hash)\u001b[0m\n\u001b[1;32m    415\u001b[0m \u001b[38;5;28;01mtry\u001b[39;00m:\n\u001b[1;32m    416\u001b[0m     \u001b[38;5;66;03m# Load from URL or cache if already cached\u001b[39;00m\n\u001b[0;32m--> 417\u001b[0m     resolved_file \u001b[38;5;241m=\u001b[39m hf_hub_download(\n\u001b[1;32m    418\u001b[0m         path_or_repo_id,\n\u001b[1;32m    419\u001b[0m         filename,\n\u001b[1;32m    420\u001b[0m         subfolder\u001b[38;5;241m=\u001b[39m\u001b[38;5;28;01mNone\u001b[39;00m \u001b[38;5;28;01mif\u001b[39;00m \u001b[38;5;28mlen\u001b[39m(subfolder) \u001b[38;5;241m==\u001b[39m \u001b[38;5;241m0\u001b[39m \u001b[38;5;28;01melse\u001b[39;00m subfolder,\n\u001b[1;32m    421\u001b[0m         repo_type\u001b[38;5;241m=\u001b[39mrepo_type,\n\u001b[1;32m    422\u001b[0m         revision\u001b[38;5;241m=\u001b[39mrevision,\n\u001b[1;32m    423\u001b[0m         cache_dir\u001b[38;5;241m=\u001b[39mcache_dir,\n\u001b[1;32m    424\u001b[0m         user_agent\u001b[38;5;241m=\u001b[39muser_agent,\n\u001b[1;32m    425\u001b[0m         force_download\u001b[38;5;241m=\u001b[39mforce_download,\n\u001b[1;32m    426\u001b[0m         proxies\u001b[38;5;241m=\u001b[39mproxies,\n\u001b[1;32m    427\u001b[0m         resume_download\u001b[38;5;241m=\u001b[39mresume_download,\n\u001b[1;32m    428\u001b[0m         use_auth_token\u001b[38;5;241m=\u001b[39muse_auth_token,\n\u001b[1;32m    429\u001b[0m         local_files_only\u001b[38;5;241m=\u001b[39mlocal_files_only,\n\u001b[1;32m    430\u001b[0m     )\n\u001b[1;32m    432\u001b[0m \u001b[38;5;28;01mexcept\u001b[39;00m RepositoryNotFoundError:\n",
      "File \u001b[0;32m~/ttmp/anaconda3/envs/baselines/lib/python3.11/site-packages/huggingface_hub/utils/_validators.py:118\u001b[0m, in \u001b[0;36mvalidate_hf_hub_args.<locals>._inner_fn\u001b[0;34m(*args, **kwargs)\u001b[0m\n\u001b[1;32m    116\u001b[0m     kwargs \u001b[38;5;241m=\u001b[39m smoothly_deprecate_use_auth_token(fn_name\u001b[38;5;241m=\u001b[39mfn\u001b[38;5;241m.\u001b[39m\u001b[38;5;18m__name__\u001b[39m, has_token\u001b[38;5;241m=\u001b[39mhas_token, kwargs\u001b[38;5;241m=\u001b[39mkwargs)\n\u001b[0;32m--> 118\u001b[0m \u001b[38;5;28;01mreturn\u001b[39;00m fn(\u001b[38;5;241m*\u001b[39margs, \u001b[38;5;241m*\u001b[39m\u001b[38;5;241m*\u001b[39mkwargs)\n",
      "File \u001b[0;32m~/ttmp/anaconda3/envs/baselines/lib/python3.11/site-packages/huggingface_hub/file_download.py:1360\u001b[0m, in \u001b[0;36mhf_hub_download\u001b[0;34m(repo_id, filename, subfolder, repo_type, revision, endpoint, library_name, library_version, cache_dir, local_dir, local_dir_use_symlinks, user_agent, force_download, force_filename, proxies, etag_timeout, resume_download, token, local_files_only, legacy_cache_layout)\u001b[0m\n\u001b[1;32m   1358\u001b[0m \u001b[38;5;28;01melif\u001b[39;00m \u001b[38;5;28misinstance\u001b[39m(head_call_error, RepositoryNotFoundError) \u001b[38;5;129;01mor\u001b[39;00m \u001b[38;5;28misinstance\u001b[39m(head_call_error, GatedRepoError):\n\u001b[1;32m   1359\u001b[0m     \u001b[38;5;66;03m# Repo not found => let's raise the actual error\u001b[39;00m\n\u001b[0;32m-> 1360\u001b[0m     \u001b[38;5;28;01mraise\u001b[39;00m head_call_error\n\u001b[1;32m   1361\u001b[0m \u001b[38;5;28;01melse\u001b[39;00m:\n\u001b[1;32m   1362\u001b[0m     \u001b[38;5;66;03m# Otherwise: most likely a connection issue or Hub downtime => let's warn the user\u001b[39;00m\n",
      "File \u001b[0;32m~/ttmp/anaconda3/envs/baselines/lib/python3.11/site-packages/huggingface_hub/file_download.py:1233\u001b[0m, in \u001b[0;36mhf_hub_download\u001b[0;34m(repo_id, filename, subfolder, repo_type, revision, endpoint, library_name, library_version, cache_dir, local_dir, local_dir_use_symlinks, user_agent, force_download, force_filename, proxies, etag_timeout, resume_download, token, local_files_only, legacy_cache_layout)\u001b[0m\n\u001b[1;32m   1232\u001b[0m \u001b[38;5;28;01mtry\u001b[39;00m:\n\u001b[0;32m-> 1233\u001b[0m     metadata \u001b[38;5;241m=\u001b[39m get_hf_file_metadata(\n\u001b[1;32m   1234\u001b[0m         url\u001b[38;5;241m=\u001b[39murl,\n\u001b[1;32m   1235\u001b[0m         token\u001b[38;5;241m=\u001b[39mtoken,\n\u001b[1;32m   1236\u001b[0m         proxies\u001b[38;5;241m=\u001b[39mproxies,\n\u001b[1;32m   1237\u001b[0m         timeout\u001b[38;5;241m=\u001b[39metag_timeout,\n\u001b[1;32m   1238\u001b[0m     )\n\u001b[1;32m   1239\u001b[0m \u001b[38;5;28;01mexcept\u001b[39;00m EntryNotFoundError \u001b[38;5;28;01mas\u001b[39;00m http_error:\n\u001b[1;32m   1240\u001b[0m     \u001b[38;5;66;03m# Cache the non-existence of the file and raise\u001b[39;00m\n",
      "File \u001b[0;32m~/ttmp/anaconda3/envs/baselines/lib/python3.11/site-packages/huggingface_hub/utils/_validators.py:118\u001b[0m, in \u001b[0;36mvalidate_hf_hub_args.<locals>._inner_fn\u001b[0;34m(*args, **kwargs)\u001b[0m\n\u001b[1;32m    116\u001b[0m     kwargs \u001b[38;5;241m=\u001b[39m smoothly_deprecate_use_auth_token(fn_name\u001b[38;5;241m=\u001b[39mfn\u001b[38;5;241m.\u001b[39m\u001b[38;5;18m__name__\u001b[39m, has_token\u001b[38;5;241m=\u001b[39mhas_token, kwargs\u001b[38;5;241m=\u001b[39mkwargs)\n\u001b[0;32m--> 118\u001b[0m \u001b[38;5;28;01mreturn\u001b[39;00m fn(\u001b[38;5;241m*\u001b[39margs, \u001b[38;5;241m*\u001b[39m\u001b[38;5;241m*\u001b[39mkwargs)\n",
      "File \u001b[0;32m~/ttmp/anaconda3/envs/baselines/lib/python3.11/site-packages/huggingface_hub/file_download.py:1622\u001b[0m, in \u001b[0;36mget_hf_file_metadata\u001b[0;34m(url, token, proxies, timeout)\u001b[0m\n\u001b[1;32m   1613\u001b[0m r \u001b[38;5;241m=\u001b[39m _request_wrapper(\n\u001b[1;32m   1614\u001b[0m     method\u001b[38;5;241m=\u001b[39m\u001b[38;5;124m\"\u001b[39m\u001b[38;5;124mHEAD\u001b[39m\u001b[38;5;124m\"\u001b[39m,\n\u001b[1;32m   1615\u001b[0m     url\u001b[38;5;241m=\u001b[39murl,\n\u001b[0;32m   (...)\u001b[0m\n\u001b[1;32m   1620\u001b[0m     timeout\u001b[38;5;241m=\u001b[39mtimeout,\n\u001b[1;32m   1621\u001b[0m )\n\u001b[0;32m-> 1622\u001b[0m hf_raise_for_status(r)\n\u001b[1;32m   1624\u001b[0m \u001b[38;5;66;03m# Return\u001b[39;00m\n",
      "File \u001b[0;32m~/ttmp/anaconda3/envs/baselines/lib/python3.11/site-packages/huggingface_hub/utils/_errors.py:285\u001b[0m, in \u001b[0;36mhf_raise_for_status\u001b[0;34m(response, endpoint_name)\u001b[0m\n\u001b[1;32m    282\u001b[0m     message \u001b[38;5;241m=\u001b[39m (\n\u001b[1;32m    283\u001b[0m         \u001b[38;5;124mf\u001b[39m\u001b[38;5;124m\"\u001b[39m\u001b[38;5;132;01m{\u001b[39;00mresponse\u001b[38;5;241m.\u001b[39mstatus_code\u001b[38;5;132;01m}\u001b[39;00m\u001b[38;5;124m Client Error.\u001b[39m\u001b[38;5;124m\"\u001b[39m \u001b[38;5;241m+\u001b[39m \u001b[38;5;124m\"\u001b[39m\u001b[38;5;130;01m\\n\u001b[39;00m\u001b[38;5;130;01m\\n\u001b[39;00m\u001b[38;5;124m\"\u001b[39m \u001b[38;5;241m+\u001b[39m \u001b[38;5;124mf\u001b[39m\u001b[38;5;124m\"\u001b[39m\u001b[38;5;124mCannot access gated repo for url \u001b[39m\u001b[38;5;132;01m{\u001b[39;00mresponse\u001b[38;5;241m.\u001b[39murl\u001b[38;5;132;01m}\u001b[39;00m\u001b[38;5;124m.\u001b[39m\u001b[38;5;124m\"\u001b[39m\n\u001b[1;32m    284\u001b[0m     )\n\u001b[0;32m--> 285\u001b[0m     \u001b[38;5;28;01mraise\u001b[39;00m GatedRepoError(message, response) \u001b[38;5;28;01mfrom\u001b[39;00m \u001b[38;5;21;01me\u001b[39;00m\n\u001b[1;32m    287\u001b[0m \u001b[38;5;28;01melif\u001b[39;00m (\n\u001b[1;32m    288\u001b[0m     response\u001b[38;5;241m.\u001b[39mstatus_code \u001b[38;5;241m==\u001b[39m \u001b[38;5;241m401\u001b[39m\n\u001b[1;32m    289\u001b[0m     \u001b[38;5;129;01mand\u001b[39;00m response\u001b[38;5;241m.\u001b[39mrequest\u001b[38;5;241m.\u001b[39murl \u001b[38;5;129;01mis\u001b[39;00m \u001b[38;5;129;01mnot\u001b[39;00m \u001b[38;5;28;01mNone\u001b[39;00m\n\u001b[0;32m   (...)\u001b[0m\n\u001b[1;32m    292\u001b[0m     \u001b[38;5;66;03m# Collection not found. We don't raise a custom error for this.\u001b[39;00m\n\u001b[1;32m    293\u001b[0m     \u001b[38;5;66;03m# This prevent from raising a misleading `RepositoryNotFoundError` (see below).\u001b[39;00m\n",
      "\u001b[0;31mGatedRepoError\u001b[0m: 401 Client Error. (Request ID: Root=1-661f4018-4ce3c4e5377f60af6551baff;cd7a3cd0-1d93-4d5f-a9fc-c95584fbf289)\n\nCannot access gated repo for url https://huggingface.co/meta-llama/Llama-2-7b-chat-hf/resolve/main/tokenizer_config.json.\nRepo model meta-llama/Llama-2-7b-chat-hf is gated. You must be authenticated to access it.",
      "\nDuring handling of the above exception, another exception occurred:\n",
      "\u001b[0;31mOSError\u001b[0m                                   Traceback (most recent call last)",
      "Cell \u001b[0;32mIn[17], line 6\u001b[0m\n\u001b[1;32m      2\u001b[0m \u001b[38;5;28;01mfrom\u001b[39;00m \u001b[38;5;21;01mtransformers\u001b[39;00m \u001b[38;5;28;01mimport\u001b[39;00m AutoTokenizer, AutoModelForCausalLM\n\u001b[1;32m      4\u001b[0m model_id \u001b[38;5;241m=\u001b[39m \u001b[38;5;124m\"\u001b[39m\u001b[38;5;124mmeta-llama/Llama-2-7b-chat-hf\u001b[39m\u001b[38;5;124m\"\u001b[39m\n\u001b[0;32m----> 6\u001b[0m t \u001b[38;5;241m=\u001b[39m AutoTokenizer\u001b[38;5;241m.\u001b[39mfrom_pretrained(model_id)\n\u001b[1;32m      7\u001b[0m t\u001b[38;5;241m.\u001b[39mpad_token \u001b[38;5;241m=\u001b[39m t\u001b[38;5;241m.\u001b[39meos_token\n\u001b[1;32m      8\u001b[0m m \u001b[38;5;241m=\u001b[39m AutoModelForCausalLM\u001b[38;5;241m.\u001b[39mfrom_pretrained(model_id, torch_dtype\u001b[38;5;241m=\u001b[39m\u001b[38;5;124m\"\u001b[39m\u001b[38;5;124mauto\u001b[39m\u001b[38;5;124m\"\u001b[39m, device_map\u001b[38;5;241m=\u001b[39m\u001b[38;5;124m\"\u001b[39m\u001b[38;5;124mauto\u001b[39m\u001b[38;5;124m\"\u001b[39m )\n",
      "File \u001b[0;32m~/ttmp/anaconda3/envs/baselines/lib/python3.11/site-packages/transformers/models/auto/tokenization_auto.py:652\u001b[0m, in \u001b[0;36mAutoTokenizer.from_pretrained\u001b[0;34m(cls, pretrained_model_name_or_path, *inputs, **kwargs)\u001b[0m\n\u001b[1;32m    649\u001b[0m     \u001b[38;5;28;01mreturn\u001b[39;00m tokenizer_class\u001b[38;5;241m.\u001b[39mfrom_pretrained(pretrained_model_name_or_path, \u001b[38;5;241m*\u001b[39minputs, \u001b[38;5;241m*\u001b[39m\u001b[38;5;241m*\u001b[39mkwargs)\n\u001b[1;32m    651\u001b[0m \u001b[38;5;66;03m# Next, let's try to use the tokenizer_config file to get the tokenizer class.\u001b[39;00m\n\u001b[0;32m--> 652\u001b[0m tokenizer_config \u001b[38;5;241m=\u001b[39m get_tokenizer_config(pretrained_model_name_or_path, \u001b[38;5;241m*\u001b[39m\u001b[38;5;241m*\u001b[39mkwargs)\n\u001b[1;32m    653\u001b[0m \u001b[38;5;28;01mif\u001b[39;00m \u001b[38;5;124m\"\u001b[39m\u001b[38;5;124m_commit_hash\u001b[39m\u001b[38;5;124m\"\u001b[39m \u001b[38;5;129;01min\u001b[39;00m tokenizer_config:\n\u001b[1;32m    654\u001b[0m     kwargs[\u001b[38;5;124m\"\u001b[39m\u001b[38;5;124m_commit_hash\u001b[39m\u001b[38;5;124m\"\u001b[39m] \u001b[38;5;241m=\u001b[39m tokenizer_config[\u001b[38;5;124m\"\u001b[39m\u001b[38;5;124m_commit_hash\u001b[39m\u001b[38;5;124m\"\u001b[39m]\n",
      "File \u001b[0;32m~/ttmp/anaconda3/envs/baselines/lib/python3.11/site-packages/transformers/models/auto/tokenization_auto.py:496\u001b[0m, in \u001b[0;36mget_tokenizer_config\u001b[0;34m(pretrained_model_name_or_path, cache_dir, force_download, resume_download, proxies, use_auth_token, revision, local_files_only, subfolder, **kwargs)\u001b[0m\n\u001b[1;32m    434\u001b[0m \u001b[38;5;250m\u001b[39m\u001b[38;5;124;03m\"\"\"\u001b[39;00m\n\u001b[1;32m    435\u001b[0m \u001b[38;5;124;03mLoads the tokenizer configuration from a pretrained model tokenizer configuration.\u001b[39;00m\n\u001b[1;32m    436\u001b[0m \n\u001b[0;32m   (...)\u001b[0m\n\u001b[1;32m    493\u001b[0m \u001b[38;5;124;03mtokenizer_config = get_tokenizer_config(\"tokenizer-test\")\u001b[39;00m\n\u001b[1;32m    494\u001b[0m \u001b[38;5;124;03m```\"\"\"\u001b[39;00m\n\u001b[1;32m    495\u001b[0m commit_hash \u001b[38;5;241m=\u001b[39m kwargs\u001b[38;5;241m.\u001b[39mget(\u001b[38;5;124m\"\u001b[39m\u001b[38;5;124m_commit_hash\u001b[39m\u001b[38;5;124m\"\u001b[39m, \u001b[38;5;28;01mNone\u001b[39;00m)\n\u001b[0;32m--> 496\u001b[0m resolved_config_file \u001b[38;5;241m=\u001b[39m cached_file(\n\u001b[1;32m    497\u001b[0m     pretrained_model_name_or_path,\n\u001b[1;32m    498\u001b[0m     TOKENIZER_CONFIG_FILE,\n\u001b[1;32m    499\u001b[0m     cache_dir\u001b[38;5;241m=\u001b[39mcache_dir,\n\u001b[1;32m    500\u001b[0m     force_download\u001b[38;5;241m=\u001b[39mforce_download,\n\u001b[1;32m    501\u001b[0m     resume_download\u001b[38;5;241m=\u001b[39mresume_download,\n\u001b[1;32m    502\u001b[0m     proxies\u001b[38;5;241m=\u001b[39mproxies,\n\u001b[1;32m    503\u001b[0m     use_auth_token\u001b[38;5;241m=\u001b[39muse_auth_token,\n\u001b[1;32m    504\u001b[0m     revision\u001b[38;5;241m=\u001b[39mrevision,\n\u001b[1;32m    505\u001b[0m     local_files_only\u001b[38;5;241m=\u001b[39mlocal_files_only,\n\u001b[1;32m    506\u001b[0m     subfolder\u001b[38;5;241m=\u001b[39msubfolder,\n\u001b[1;32m    507\u001b[0m     _raise_exceptions_for_missing_entries\u001b[38;5;241m=\u001b[39m\u001b[38;5;28;01mFalse\u001b[39;00m,\n\u001b[1;32m    508\u001b[0m     _raise_exceptions_for_connection_errors\u001b[38;5;241m=\u001b[39m\u001b[38;5;28;01mFalse\u001b[39;00m,\n\u001b[1;32m    509\u001b[0m     _commit_hash\u001b[38;5;241m=\u001b[39mcommit_hash,\n\u001b[1;32m    510\u001b[0m )\n\u001b[1;32m    511\u001b[0m \u001b[38;5;28;01mif\u001b[39;00m resolved_config_file \u001b[38;5;129;01mis\u001b[39;00m \u001b[38;5;28;01mNone\u001b[39;00m:\n\u001b[1;32m    512\u001b[0m     logger\u001b[38;5;241m.\u001b[39minfo(\u001b[38;5;124m\"\u001b[39m\u001b[38;5;124mCould not locate the tokenizer configuration file, will try to use the model config instead.\u001b[39m\u001b[38;5;124m\"\u001b[39m)\n",
      "File \u001b[0;32m~/ttmp/anaconda3/envs/baselines/lib/python3.11/site-packages/transformers/utils/hub.py:433\u001b[0m, in \u001b[0;36mcached_file\u001b[0;34m(path_or_repo_id, filename, cache_dir, force_download, resume_download, proxies, use_auth_token, revision, local_files_only, subfolder, repo_type, user_agent, _raise_exceptions_for_missing_entries, _raise_exceptions_for_connection_errors, _commit_hash)\u001b[0m\n\u001b[1;32m    417\u001b[0m     resolved_file \u001b[38;5;241m=\u001b[39m hf_hub_download(\n\u001b[1;32m    418\u001b[0m         path_or_repo_id,\n\u001b[1;32m    419\u001b[0m         filename,\n\u001b[0;32m   (...)\u001b[0m\n\u001b[1;32m    429\u001b[0m         local_files_only\u001b[38;5;241m=\u001b[39mlocal_files_only,\n\u001b[1;32m    430\u001b[0m     )\n\u001b[1;32m    432\u001b[0m \u001b[38;5;28;01mexcept\u001b[39;00m RepositoryNotFoundError:\n\u001b[0;32m--> 433\u001b[0m     \u001b[38;5;28;01mraise\u001b[39;00m \u001b[38;5;167;01mEnvironmentError\u001b[39;00m(\n\u001b[1;32m    434\u001b[0m         \u001b[38;5;124mf\u001b[39m\u001b[38;5;124m\"\u001b[39m\u001b[38;5;132;01m{\u001b[39;00mpath_or_repo_id\u001b[38;5;132;01m}\u001b[39;00m\u001b[38;5;124m is not a local folder and is not a valid model identifier \u001b[39m\u001b[38;5;124m\"\u001b[39m\n\u001b[1;32m    435\u001b[0m         \u001b[38;5;124m\"\u001b[39m\u001b[38;5;124mlisted on \u001b[39m\u001b[38;5;124m'\u001b[39m\u001b[38;5;124mhttps://huggingface.co/models\u001b[39m\u001b[38;5;124m'\u001b[39m\u001b[38;5;130;01m\\n\u001b[39;00m\u001b[38;5;124mIf this is a private repository, make sure to \u001b[39m\u001b[38;5;124m\"\u001b[39m\n\u001b[1;32m    436\u001b[0m         \u001b[38;5;124m\"\u001b[39m\u001b[38;5;124mpass a token having permission to this repo with `use_auth_token` or log in with \u001b[39m\u001b[38;5;124m\"\u001b[39m\n\u001b[1;32m    437\u001b[0m         \u001b[38;5;124m\"\u001b[39m\u001b[38;5;124m`huggingface-cli login` and pass `use_auth_token=True`.\u001b[39m\u001b[38;5;124m\"\u001b[39m\n\u001b[1;32m    438\u001b[0m     )\n\u001b[1;32m    439\u001b[0m \u001b[38;5;28;01mexcept\u001b[39;00m RevisionNotFoundError:\n\u001b[1;32m    440\u001b[0m     \u001b[38;5;28;01mraise\u001b[39;00m \u001b[38;5;167;01mEnvironmentError\u001b[39;00m(\n\u001b[1;32m    441\u001b[0m         \u001b[38;5;124mf\u001b[39m\u001b[38;5;124m\"\u001b[39m\u001b[38;5;132;01m{\u001b[39;00mrevision\u001b[38;5;132;01m}\u001b[39;00m\u001b[38;5;124m is not a valid git identifier (branch name, tag name or commit id) that exists \u001b[39m\u001b[38;5;124m\"\u001b[39m\n\u001b[1;32m    442\u001b[0m         \u001b[38;5;124m\"\u001b[39m\u001b[38;5;124mfor this model name. Check the model page at \u001b[39m\u001b[38;5;124m\"\u001b[39m\n\u001b[1;32m    443\u001b[0m         \u001b[38;5;124mf\u001b[39m\u001b[38;5;124m\"\u001b[39m\u001b[38;5;124m'\u001b[39m\u001b[38;5;124mhttps://huggingface.co/\u001b[39m\u001b[38;5;132;01m{\u001b[39;00mpath_or_repo_id\u001b[38;5;132;01m}\u001b[39;00m\u001b[38;5;124m'\u001b[39m\u001b[38;5;124m for available revisions.\u001b[39m\u001b[38;5;124m\"\u001b[39m\n\u001b[1;32m    444\u001b[0m     )\n",
      "\u001b[0;31mOSError\u001b[0m: meta-llama/Llama-2-7b-chat-hf is not a local folder and is not a valid model identifier listed on 'https://huggingface.co/models'\nIf this is a private repository, make sure to pass a token having permission to this repo with `use_auth_token` or log in with `huggingface-cli login` and pass `use_auth_token=True`."
     ]
    }
   ],
   "source": [
    "import torch\n",
    "from transformers import AutoTokenizer, AutoModelForCausalLM\n",
    "\n",
    "model_id = \"meta-llama/Llama-2-7b-chat-hf\"\n",
    "\n",
    "t = AutoTokenizer.from_pretrained(model_id)\n",
    "t.pad_token = t.eos_token\n",
    "m = AutoModelForCausalLM.from_pretrained(model_id, torch_dtype=\"auto\", device_map=\"auto\" )\n",
    "m.eval()\n",
    "\n",
    "\n",
    "texts = [\n",
    "    \"this is a test\",\n",
    "    \"this is another test case with a different length\",\n",
    "]\n",
    "t_input = t(texts, padding=True, return_tensors=\"pt\")\n",
    "\n",
    "\n",
    "with torch.no_grad():\n",
    "    last_hidden_state = m(**t_input, output_hidden_states=True).hidden_states[-1]\n",
    "\n",
    "\n",
    "weights_for_non_padding = t_input.attention_mask * torch.arange(start=1, end=last_hidden_state.shape[1] + 1).unsqueeze(0)\n",
    "\n",
    "sum_embeddings = torch.sum(last_hidden_state * weights_for_non_padding.unsqueeze(-1), dim=1)\n",
    "num_of_none_padding_tokens = torch.sum(weights_for_non_padding, dim=-1).unsqueeze(-1)\n",
    "sentence_embeddings = sum_embeddings / num_of_none_padding_tokens\n",
    "\n",
    "print(t_input.input_ids)\n",
    "print(weights_for_non_padding)\n",
    "print(num_of_none_padding_tokens)\n",
    "print(sentence_embeddings.shape)"
   ]
  },
  {
   "cell_type": "code",
   "execution_count": null,
   "metadata": {},
   "outputs": [],
   "source": []
  }
 ],
 "metadata": {
  "kernelspec": {
   "display_name": "baselines",
   "language": "python",
   "name": "python3"
  },
  "language_info": {
   "codemirror_mode": {
    "name": "ipython",
    "version": 3
   },
   "file_extension": ".py",
   "mimetype": "text/x-python",
   "name": "python",
   "nbconvert_exporter": "python",
   "pygments_lexer": "ipython3",
   "version": "3.11.5"
  }
 },
 "nbformat": 4,
 "nbformat_minor": 2
}
